<?xml version="1.0"?>
<sdf version="1.6">
  <model name="cable">
    <link name="base_link">
      <inertial>
        <pose>0 0 0 0 0 0</pose>
        <mass>0.00001</mass>
        <inertia>
          <ixx>0.0000016833</ixx>
          <ixy>0</ixy>
          <ixz>0</ixz>
          <iyy>0.0000016833</iyy>
          <iyz>0</iyz>
          <izz>0.00000005</izz>
        </inertia>
      </inertial>
      <visual name="base_visual">
        <pose>0 0 -0.055 0 0 0</pose>
        <geometry>
          <cylinder>
            <radius>0.005</radius> 
            <length>0.1</length>   
          </cylinder>
        </geometry>
        <material>
          <ambient>0.1 0.1 0.8 1</ambient> 
          <diffuse>0.1 0.1 0.8 1</diffuse>
          <specular>0.1 0.1 0.1 1</specular>
        </material>
      </visual>
    </link>
  
    <link name="link1">
    <inertial>
        <pose>0 0 0 0 0 0</pose>
        <mass>0.00001</mass>
        <inertia>
          <ixx>0.0000016833</ixx>
          <ixy>0</ixy>
          <ixz>0</ixz>
          <iyy>0.0000016833</iyy>
          <iyz>0</iyz>
          <izz>0.00000005</izz>
        </inertia>
    </inertial>
      <pose>0 0 -0.105 0 0 0</pose>
      <visual name="visual1">
        <pose>0 0 -0.055 0 0 0</pose>
        <geometry>
          <cylinder>
            <radius>0.005</radius> 
            <length>0.1</length>   
          </cylinder>
        </geometry>
        <material>
          <ambient>0.1 0.1 0.8 1</ambient> 
          <diffuse>0.1 0.1 0.8 1</diffuse>
          <specular>0.1 0.1 0.1 1</specular>
        </material>
      </visual>
    </link>
  
    <link name="link2">
    <inertial>
        <pose>0 0 0 0 0 0</pose>
        <mass>0.00001</mass>
        <inertia>
          <ixx>0.0000016833</ixx>
          <ixy>0</ixy>
          <ixz>0</ixz>
          <iyy>0.0000016833</iyy>
          <iyz>0</iyz>
          <izz>0.00000005</izz>
        </inertia>
    </inertial>
      <pose>0 0 -0.205 0 0 0</pose>
      <visual name="visual2">
      <pose>0 0 -0.055 0 0 0</pose>
        <geometry>
          <cylinder>
            <radius>0.005</radius> 
            <length>0.1</length>   
          </cylinder>
        </geometry>
        <material>
          <ambient>0.1 0.1 0.8 1</ambient> 
          <diffuse>0.1 0.1 0.8 1</diffuse>
          <specular>0.1 0.1 0.1 1</specular>
        </material>
      </visual>
    </link>
  
    <link name="link3">
    <inertial>
        <pose>0 0 0 0 0 0</pose>
        <mass>0.00001</mass>
        <inertia>
          <ixx>0.0000016833</ixx>
          <ixy>0</ixy>
          <ixz>0</ixz>
          <iyy>0.0000016833</iyy>
          <iyz>0</iyz>
          <izz>0.00000005</izz>
        </inertia>
    </inertial>
      <pose>0 0 -0.305 0 0 0</pose>
      <visual name="visual3">
      <pose>0 0 -0.055 0 0 0</pose>
        <geometry>
          <cylinder>
            <radius>0.005</radius> 
            <length>0.1</length>   
          </cylinder>
        </geometry>
        <material>
          <ambient>0.1 0.1 0.8 1</ambient> 
          <diffuse>0.1 0.1 0.8 1</diffuse>
          <specular>0.1 0.1 0.1 1</specular>
        </material>
      </visual>
    </link>
  
    <link name="link4">
    <inertial>
        <pose>0 0 0 0 0 0</pose>
        <mass>0.00001</mass>
        <inertia>
          <ixx>0.0000016833</ixx>
          <ixy>0</ixy>
          <ixz>0</ixz>
          <iyy>0.0000016833</iyy>
          <iyz>0</iyz>
          <izz>0.00000005</izz>
        </inertia>
    </inertial>
      <pose>0 0 -0.405 0 0 0</pose>
      <visual name="visual4">
      <pose>0 0 -0.055 0 0 0</pose>
        <geometry>
          <cylinder>
            <radius>0.005</radius> 
            <length>0.1</length> 
          </cylinder>
        </geometry>
        <material>
          <ambient>0.1 0.1 0.8 1</ambient> 
          <diffuse>0.1 0.1 0.8 1</diffuse>
          <specular>0.1 0.1 0.1 1</specular>
        </material>
      </visual>
    </link>
  
    <link name="link5">
    <inertial>
        <pose>0 0 0 0 0 0</pose>
        <mass>0.00001</mass>
        <inertia>
          <ixx>0.0000016833</ixx>
          <ixy>0</ixy>
          <ixz>0</ixz>
          <iyy>0.0000016833</iyy>
          <iyz>0</iyz>
          <izz>0.00000005</izz>
        </inertia>
    </inertial>
      <pose>0 0 -0.505 0 0 0</pose>
      <visual name="visual5">
      <pose>0 0 -0.055 0 0 0</pose>
        <geometry>
          <cylinder>
            <radius>0.005</radius> 
            <length>0.1</length> 
          </cylinder>
        </geometry>
        <material>
          <ambient>0.1 0.1 0.8 1</ambient> 
          <diffuse>0.1 0.1 0.8 1</diffuse>
          <specular>0.1 0.1 0.1 1</specular>
        </material>
      </visual>
    </link>
  
    <link name="link6">
    <inertial>
        <pose>0 0 0 0 0 0</pose>
        <mass>0.00001</mass>
        <inertia>
          <ixx>0.0000016833</ixx>
          <ixy>0</ixy>
          <ixz>0</ixz>
          <iyy>0.0000016833</iyy>
          <iyz>0</iyz>
          <izz>0.00000005</izz>
        </inertia>
    </inertial>
      <pose>0 0 -0.605 0 0 0</pose>
      <visual name="visual6">
      <pose>0 0 -0.055 0 0 0</pose>
        <geometry>
          <cylinder>
            <radius>0.005</radius> 
            <length>0.1</length> 
          </cylinder>
        </geometry>
        <material>
          <ambient>0.1 0.1 0.8 1</ambient> 
          <diffuse>0.1 0.1 0.8 1</diffuse>
          <specular>0.1 0.1 0.1 1</specular>
        </material>
      </visual>
    </link>
  
    <link name="link7">
    <inertial>
        <pose>0 0 0 0 0 0</pose>
        <mass>0.00001</mass>
        <inertia>
          <ixx>0.0000016833</ixx>
          <ixy>0</ixy>
          <ixz>0</ixz>
          <iyy>0.0000016833</iyy>
          <iyz>0</iyz>
          <izz>0.00000005</izz>
        </inertia>
    </inertial>
      <pose>0 0 -0.705 0 0 0</pose>
      <visual name="visual7">
      <pose>0 0 -0.055 0 0 0</pose>
        <geometry>
          <cylinder>
            <radius>0.005</radius> 
            <length>0.1</length> 
          </cylinder>
        </geometry>
        <material>
          <ambient>0.1 0.1 0.8 1</ambient> 
          <diffuse>0.1 0.1 0.8 1</diffuse>
          <specular>0.1 0.1 0.1 1</specular>
        </material>
      </visual>
    </link>

    <joint name='joint0' type='revolute'>
        <child>link1</child>
      <parent>base_link</parent>
      <axis>
        <xyz>0 1 0</xyz>
        <limit>
          <lower>-3.14/3</lower>
          <upper>3.14/3</upper>
        </limit>
        <dynamics>
          <damping>0.4</damping>
        </dynamics>
      </axis>
      <physics>
        <ode>
          <implicit_spring_damper>1</implicit_spring_damper>
        </ode>
      </physics>
    </joint>

    <joint name='joint1' type='revolute'>
        <child>link2</child>
      <parent>link1</parent>
      <axis>
        <xyz>1 0 0</xyz>
        <limit>
          <lower>-3.14/3</lower>
          <upper>3.14/3</upper>
        </limit>
        <dynamics>
          <damping>0.4</damping>
        </dynamics>
      </axis>
      <physics>
        <ode>
          <implicit_spring_damper>1</implicit_spring_damper>
        </ode>
      </physics>
    </joint>

    <joint name='joint2' type='revolute'>
        <child>link3</child>
      <parent>link2</parent>
      <axis>
        <xyz>0 1 0</xyz>
        <limit>
          <lower>-3.14/3</lower>
          <upper>3.14/3</upper>
        </limit>
        <dynamics>
          <damping>0.4</damping>
        </dynamics>
      </axis>
      <physics>
        <ode>
          <implicit_spring_damper>1</implicit_spring_damper>
        </ode>
      </physics>
    </joint>

    <joint name='joint3' type='revolute'>
      <child>link4</child>
      <parent>link3</parent>
      <axis>
        <xyz>1 0 0</xyz>
        <limit>
          <lower>-3.14/3</lower>
          <upper>3.14/3</upper>
        </limit>
        <dynamics>
          <damping>0.4</damping>
        </dynamics>
      </axis>
      <physics>
        <ode>
          <implicit_spring_damper>1</implicit_spring_damper>
        </ode>
      </physics>
    </joint>

    <joint name='joint4' type='revolute'>
      <child>link5</child>
      <parent>link4</parent>
      <axis>
        <xyz>0 1 0</xyz>
        <limit>
          <lower>-3.14/3</lower>
          <upper>3.14/3</upper>
        </limit>
        <dynamics>
          <damping>0.4</damping>
        </dynamics>
      </axis>
      <physics>
        <ode>
          <implicit_spring_damper>1</implicit_spring_damper>
        </ode>
      </physics>
    </joint>

    <joint name='joint5' type='revolute'>
      <child>link6</child>
      <parent>link5</parent>
      <axis>
        <xyz>1 0 0</xyz>
        <limit>
          <lower>-3.14/3</lower>
          <upper>3.14/3</upper>
        </limit>
        <dynamics>
          <damping>0.4</damping>
        </dynamics>
      </axis>
      <physics>
        <ode>
          <implicit_spring_damper>1</implicit_spring_damper>
        </ode>
      </physics>
    </joint>

    <joint name='joint6' type='revolute'>
      <child>link7</child>
      <parent>link6</parent>
      <axis>
        <xyz>0 1 0</xyz>
        <limit>
          <lower>-3.14/3</lower>
          <upper>3.14/3</upper>
        </limit>
        <dynamics>
          <damping>0.4</damping>
        </dynamics>
      </axis>
      <physics>
        <ode>
          <implicit_spring_damper>1</implicit_spring_damper>
        </ode>
      </physics>
    </joint>



  </model>
</sdf>
